multiprocessing.pool.RemoteTraceback: 
"""
Traceback (most recent call last):
  File "/usr/licensed/anaconda3/2021.5/lib/python3.8/multiprocessing/pool.py", line 125, in worker
    result = (True, func(*args, **kwds))
  File "/usr/licensed/anaconda3/2021.5/lib/python3.8/multiprocessing/pool.py", line 48, in mapstar
    return list(map(*args))
  File "3body.py", line 267, in run_sim
    integrate_sim(dir_path,sim_params,trial_num,tf,nv,inds,out_step)
  File "3body.py", line 180, in integrate_sim
    sim.integrate(i*step*year)
  File "/u/hdyuan/.local/lib/python3.8/site-packages/rebound/simulation.py", line 2100, in integrate
    self.process_messages()
  File "/u/hdyuan/.local/lib/python3.8/site-packages/rebound/simulation.py", line 1034, in process_messages
    raise RuntimeError(msg[1:])
RuntimeError: REBOUNDx Error: triaxial_torque: Vectors i, j, and k must be mutually orthogonal.

"""

The above exception was the direct cause of the following exception:

Traceback (most recent call last):
  File "3body.py", line 280, in <module>
    pool.map(run_sim, range(n_trials))
  File "/usr/licensed/anaconda3/2021.5/lib/python3.8/multiprocessing/pool.py", line 364, in map
    return self._map_async(func, iterable, mapstar, chunksize).get()
  File "/usr/licensed/anaconda3/2021.5/lib/python3.8/multiprocessing/pool.py", line 771, in get
    raise self._value
RuntimeError: REBOUNDx Error: triaxial_torque: Vectors i, j, and k must be mutually orthogonal.

